Traceback (most recent call last):
  File "/home/placebo/eit/autoencoder/eit.py", line 147, in <module>
    with open(id_config, 'w') as f:
         ^^^^^^^^^^^^^^^^^^^^
FileNotFoundError: [Errno 2] No such file or directory: '20231004044442048640_./input/0004.yml'
